<sdf version='1.9'>
  <model name='chessaton'>
    <joint name='virtual_joint' type='fixed'>
      <pose relative_to='__model__'>0 0 0 0 0 0</pose>
      <parent>world</parent>
      <child>chessaton_link0</child>
    </joint>
    <link name='chessaton_link0'>
      <pose relative_to='virtual_joint'>0 0 0 0 0 0</pose>
      <inertial>
        <pose>-0.00088323 -3.593e-07 0.021799 0 0 0</pose>
        <mass>0.34999999999999998</mass>
        <inertia>
          <ixx>0.00040857000000000003</ixx>
          <ixy>-1.2568e-09</ixy>
          <ixz>-4.0914999999999998e-09</ixz>
          <iyy>0.00041214000000000002</iyy>
          <iyz>1.5948e-10</iyz>
          <izz>0.00079973000000000002</izz>
        </inertia>
      </inertial>
      <collision name='chessaton_link0_collision'>
        <pose>0 0 0 0 0 0</pose>
        <geometry>
          <mesh>
            <scale>1 1 1</scale>
            <uri>file:///home/ros/workspace/install/chessaton_description/share/chessaton_description/meshes/chessaton_link0.STL</uri>
          </mesh>
        </geometry>
        <surface>
          <contact>
            <ode>
              <kp>1000000</kp>
              <kd>1</kd>
            </ode>
          </contact>
          <friction>
            <ode>
              <mu>0.84999999999999998</mu>
              <mu2>0.84999999999999998</mu2>
            </ode>
          </friction>
        </surface>
      </collision>
      <visual name='chessaton_link0_visual'>
        <pose>0 0 0 0 0 0</pose>
        <geometry>
          <mesh>
            <scale>1 1 1</scale>
            <uri>file:///home/ros/workspace/install/chessaton_description/share/chessaton_description/meshes/chessaton_link0.STL</uri>
          </mesh>
        </geometry>
        <material>
          <script>
            <name>Gazebo/Grey</name>
            <uri>file://media/materials/scripts/gazebo.material</uri>
          </script>
          <diffuse>1 1 1 1</diffuse>
          <ambient>1 1 1 1</ambient>
        </material>
      </visual>
      <self_collide>false</self_collide>
    </link>
    <joint name='chessaton_joint1' type='revolute'>
      <pose relative_to='chessaton_link0'>0 0 0.07184 0 0 0</pose>
      <parent>chessaton_link0</parent>
      <child>chessaton_link1</child>
      <axis>
        <xyz>0 0 -1</xyz>
        <limit>
          <lower>-1.570796326794897</lower>
          <upper>1.570796326794897</upper>
          <effort>0</effort>
          <velocity>0.29999999999999999</velocity>
        </limit>
        <dynamics>
          <damping>0.10000000000000001</damping>
          <friction>0.10000000000000001</friction>
          <spring_reference>0</spring_reference>
          <spring_stiffness>0</spring_stiffness>
        </dynamics>
      </axis>
    </joint>
    <link name='chessaton_link1'>
      <pose relative_to='chessaton_joint1'>0 0 0 0 0 0</pose>
      <inertial>
        <pose>-2.4829e-06 1.8095e-11 0.025578 0 0 0</pose>
        <mass>0.11600000000000001</mass>
        <inertia>
          <ixx>5.4663000000000002e-05</ixx>
          <ixy>-1.3316000000000001e-07</ixy>
          <ixz>3.3525999999999998e-14</ixz>
          <iyy>4.2517e-05</iyy>
          <iyz>-8.2983000000000006e-14</iyz>
          <izz>8.9443000000000004e-05</izz>
        </inertia>
      </inertial>
      <collision name='chessaton_link1_collision'>
        <pose>0 0 0 0 0 0</pose>
        <geometry>
          <mesh>
            <scale>1 1 1</scale>
            <uri>file:///home/ros/workspace/install/chessaton_description/share/chessaton_description/meshes/chessaton_link1.STL</uri>
          </mesh>
        </geometry>
        <surface>
          <contact>
            <ode>
              <kp>1000000</kp>
              <kd>1</kd>
            </ode>
          </contact>
          <friction>
            <ode>
              <mu>0.84999999999999998</mu>
              <mu2>0.84999999999999998</mu2>
            </ode>
          </friction>
        </surface>
      </collision>
      <visual name='chessaton_link1_visual'>
        <pose>0 0 0 0 0 0</pose>
        <geometry>
          <mesh>
            <scale>1 1 1</scale>
            <uri>file:///home/ros/workspace/install/chessaton_description/share/chessaton_description/meshes/chessaton_link1.STL</uri>
          </mesh>
        </geometry>
        <material>
          <script>
            <name>Gazebo/Grey</name>
            <uri>file://media/materials/scripts/gazebo.material</uri>
          </script>
          <diffuse>0.62255 0.62255 0.62255 1</diffuse>
          <ambient>0.62255 0.62255 0.62255 1</ambient>
        </material>
      </visual>
      <self_collide>false</self_collide>
    </link>
    <joint name='chessaton_joint2' type='revolute'>
      <pose relative_to='chessaton_link1'>0 1.29770906784333e-05 0.0305688591051693 0 0 0</pose>
      <parent>chessaton_link1</parent>
      <child>chessaton_link2</child>
      <axis>
        <xyz>0 1 0</xyz>
        <limit>
          <lower>-1.570796326794897</lower>
          <upper>1.570796326794897</upper>
          <effort>0</effort>
          <velocity>0.29999999999999999</velocity>
        </limit>
        <dynamics>
          <damping>0.10000000000000001</damping>
          <friction>0.10000000000000001</friction>
          <spring_reference>0</spring_reference>
          <spring_stiffness>0</spring_stiffness>
        </dynamics>
      </axis>
    </joint>
    <link name='chessaton_link2'>
      <pose relative_to='chessaton_joint2'>0 0 0 0 0 0</pose>
      <inertial>
        <pose>-2.3338e-06 4.5723e-05 0.093503 0 0 0</pose>
        <mass>0.070999999999999994</mass>
        <inertia>
          <ixx>6.1321000000000005e-05</ixx>
          <ixy>-6.9446999999999998e-10</ixy>
          <ixz>4.4166000000000004e-12</ixz>
          <iyy>3.6390000000000002e-05</iyy>
          <iyz>-4.4750999999999998e-13</iyz>
          <izz>3.1035999999999999e-05</izz>
        </inertia>
      </inertial>
      <collision name='chessaton_link2_collision'>
        <pose>0 0 0 0 0 0</pose>
        <geometry>
          <mesh>
            <scale>1 1 1</scale>
            <uri>file:///home/ros/workspace/install/chessaton_description/share/chessaton_description/meshes/chessaton_link2.STL</uri>
          </mesh>
        </geometry>
        <surface>
          <contact>
            <ode>
              <kp>1000000</kp>
              <kd>1</kd>
            </ode>
          </contact>
          <friction>
            <ode>
              <mu>0.84999999999999998</mu>
              <mu2>0.84999999999999998</mu2>
            </ode>
          </friction>
        </surface>
      </collision>
      <visual name='chessaton_link2_visual'>
        <pose>0 0 0 0 0 0</pose>
        <geometry>
          <mesh>
            <scale>1 1 1</scale>
            <uri>file:///home/ros/workspace/install/chessaton_description/share/chessaton_description/meshes/chessaton_link2.STL</uri>
          </mesh>
        </geometry>
        <material>
          <script>
            <name>Gazebo/Grey</name>
            <uri>file://media/materials/scripts/gazebo.material</uri>
          </script>
          <diffuse>0.941176 0.941176 0.941176 1</diffuse>
          <ambient>0.941176 0.941176 0.941176 1</ambient>
        </material>
      </visual>
      <self_collide>false</self_collide>
    </link>
    <joint name='chessaton_joint3' type='revolute'>
      <pose relative_to='chessaton_link2'>0 0.025345720651074 0.187006906655083 0 0 0</pose>
      <parent>chessaton_link2</parent>
      <child>chessaton_link3</child>
      <axis>
        <xyz>0 1 0</xyz>
        <limit>
          <lower>-1.570796326794897</lower>
          <upper>1.570796326794897</upper>
          <effort>0</effort>
          <velocity>0.29999999999999999</velocity>
        </limit>
        <dynamics>
          <damping>0.10000000000000001</damping>
          <friction>0.10000000000000001</friction>
          <spring_reference>0</spring_reference>
          <spring_stiffness>0</spring_stiffness>
        </dynamics>
      </axis>
    </joint>
    <link name='chessaton_link3'>
      <pose relative_to='chessaton_joint3'>0 0 0 0 0 0</pose>
      <inertial>
        <pose>0.041523 -0.024547 -0.0018439 0 0 0</pose>
        <mass>0.01</mass>
        <inertia>
          <ixx>2.455e-05</ixx>
          <ixy>-7.2470000000000003e-09</ixy>
          <ixz>-2.7697000000000002e-07</ixz>
          <iyy>3.4978000000000003e-05</iyy>
          <iyz>4.524e-07</iyz>
          <izz>5.1335000000000002e-05</izz>
        </inertia>
      </inertial>
      <collision name='chessaton_link3_collision'>
        <pose>0 0 0 0 0 0</pose>
        <geometry>
          <mesh>
            <scale>1 1 1</scale>
            <uri>file:///home/ros/workspace/install/chessaton_description/share/chessaton_description/meshes/chessaton_link3.STL</uri>
          </mesh>
        </geometry>
        <surface>
          <contact>
            <ode>
              <kp>1000000</kp>
              <kd>1</kd>
            </ode>
          </contact>
          <friction>
            <ode>
              <mu>0.84999999999999998</mu>
              <mu2>0.84999999999999998</mu2>
            </ode>
          </friction>
        </surface>
      </collision>
      <visual name='chessaton_link3_visual'>
        <pose>0 0 0 0 0 0</pose>
        <geometry>
          <mesh>
            <scale>1 1 1</scale>
            <uri>file:///home/ros/workspace/install/chessaton_description/share/chessaton_description/meshes/chessaton_link3.STL</uri>
          </mesh>
        </geometry>
        <material>
          <script>
            <name>Gazebo/Grey</name>
            <uri>file://media/materials/scripts/gazebo.material</uri>
          </script>
          <diffuse>0.941176 0.941176 0.941176 1</diffuse>
          <ambient>0.941176 0.941176 0.941176 1</ambient>
        </material>
      </visual>
      <self_collide>false</self_collide>
    </link>
    <joint name='chessaton_joint4' type='revolute'>
      <pose relative_to='chessaton_link3'>0.157407990853242 0.00282292319687479 -0.000108863252950619 0 0 0</pose>
      <parent>chessaton_link3</parent>
      <child>chessaton_link4</child>
      <axis>
        <xyz>0 1 0</xyz>
        <limit>
          <lower>-1.570796326794897</lower>
          <upper>1.570796326794897</upper>
          <effort>0</effort>
          <velocity>0.29999999999999999</velocity>
        </limit>
        <dynamics>
          <damping>0.10000000000000001</damping>
          <friction>0.10000000000000001</friction>
          <spring_reference>0</spring_reference>
          <spring_stiffness>0</spring_stiffness>
        </dynamics>
      </axis>
    </joint>
    <link name='chessaton_link4'>
      <pose relative_to='chessaton_joint4'>0 0 0 0 0 0</pose>
      <inertial>
        <pose>0.02683363885910224 -0.0227045149743018 -0.01030261214487833 0 0 0</pose>
        <mass>0.1125</mass>
        <inertia>
          <ixx>3.522810161290297e-05</ixx>
          <ixy>-8.5942234932725127e-06</ixy>
          <ixz>9.3401235384077093e-07</ixz>
          <iyy>6.6674628198797159e-05</iyy>
          <iyz>7.7740711555380966e-08</iyz>
          <izz>7.824765285932461e-05</izz>
        </inertia>
      </inertial>
      <collision name='chessaton_link4_collision'>
        <pose>0 0 0 0 0 0</pose>
        <geometry>
          <mesh>
            <scale>1 1 1</scale>
            <uri>file:///home/ros/workspace/install/chessaton_description/share/chessaton_description/meshes/chessaton_link4.STL</uri>
          </mesh>
        </geometry>
        <surface>
          <contact>
            <ode>
              <kp>1000000</kp>
              <kd>1</kd>
            </ode>
          </contact>
          <friction>
            <ode>
              <mu>0.84999999999999998</mu>
              <mu2>0.84999999999999998</mu2>
            </ode>
          </friction>
        </surface>
      </collision>
      <collision name='chessaton_link4_fixed_joint_lump__chessaton_gripper_collision_1'>
        <pose>0.070608507146197 -0.0126359232516508 -0.0087074752469517 0 0 0</pose>
        <geometry>
          <mesh>
            <scale>1 1 1</scale>
            <uri>file:///home/ros/workspace/install/chessaton_description/share/chessaton_description/meshes/chessaton_gripper.STL</uri>
          </mesh>
        </geometry>
        <surface>
          <contact>
            <ode>
              <kp>1000000</kp>
              <kd>1</kd>
            </ode>
          </contact>
          <friction>
            <ode>
              <mu>0.84999999999999998</mu>
              <mu2>0.84999999999999998</mu2>
            </ode>
          </friction>
        </surface>
      </collision>
      <visual name='chessaton_link4_visual'>
        <pose>0 0 0 0 0 0</pose>
        <geometry>
          <mesh>
            <scale>1 1 1</scale>
            <uri>file:///home/ros/workspace/install/chessaton_description/share/chessaton_description/meshes/chessaton_link4.STL</uri>
          </mesh>
        </geometry>
        <material>
          <script>
            <name>Gazebo/Grey</name>
            <uri>file://media/materials/scripts/gazebo.material</uri>
          </script>
          <diffuse>0.941175 0.941175 0.941175 1</diffuse>
          <ambient>0.941175 0.941175 0.941175 1</ambient>
        </material>
      </visual>
      <visual name='chessaton_link4_fixed_joint_lump__chessaton_gripper_visual_1'>
        <pose>0.070608507146197 -0.0126359232516508 -0.0087074752469517 0 0 0</pose>
        <geometry>
          <mesh>
            <scale>1 1 1</scale>
            <uri>file:///home/ros/workspace/install/chessaton_description/share/chessaton_description/meshes/chessaton_gripper.STL</uri>
          </mesh>
        </geometry>
        <material>
          <script>
            <name>Gazebo/Grey</name>
            <uri>file://media/materials/scripts/gazebo.material</uri>
          </script>
          <diffuse>0.62255 0.62255 0.62255 1</diffuse>
          <ambient>0.62255 0.62255 0.62255 1</ambient>
        </material>
      </visual>
      <self_collide>false</self_collide>
    </link>
    <joint name='chessaton_hand_tcp_roll_virtual_joint' type='revolute'>
      <pose relative_to='chessaton_link4'>0.100608507146197 -0.0126359232516508 -0.0087074752469517 0 0 0</pose>
      <parent>chessaton_link4</parent>
      <child>chessaton_hand_tcp_roll</child>
      <axis>
        <xyz>-1 0 0</xyz>
        <limit>
          <lower>-1.570796326794897</lower>
          <upper>1.570796326794897</upper>
          <effort>0</effort>
          <velocity>6</velocity>
        </limit>
        <dynamics>
          <damping>1</damping>
          <friction>1</friction>
          <spring_reference>0</spring_reference>
          <spring_stiffness>0</spring_stiffness>
        </dynamics>
      </axis>
    </joint>
    <link name='chessaton_hand_tcp_roll'>
      <pose relative_to='chessaton_hand_tcp_roll_virtual_joint'>0 0 0 0 0 0</pose>
      <inertial>
        <pose>0.011394 -0.0086324 -0.005 0 0 0</pose>
        <mass>0.0088000000000000005</mass>
        <inertia>
          <ixx>6.0645999999999999e-07</ixx>
          <ixy>-1.4140999999999999e-07</ixy>
          <ixz>1.2141999999999999e-21</ixz>
          <iyy>9.0396999999999996e-07</iyy>
          <iyz>7.2150999999999998e-22</iyz>
          <izz>8.4376999999999999e-07</izz>
        </inertia>
      </inertial>
      <self_collide>false</self_collide>
    </link>
    <joint name='chessaton_hand_tcp_yaw_virtual_joint' type='revolute'>
      <pose relative_to='chessaton_hand_tcp_roll'>0 0 0 0 0 0</pose>
      <parent>chessaton_hand_tcp_roll</parent>
      <child>chessaton_hand_tcp_yaw</child>
      <axis>
        <xyz>0 0 -1</xyz>
        <limit>
          <lower>-1.570796326794897</lower>
          <upper>1.570796326794897</upper>
          <effort>0</effort>
          <velocity>6</velocity>
        </limit>
        <dynamics>
          <damping>1</damping>
          <friction>1</friction>
          <spring_reference>0</spring_reference>
          <spring_stiffness>0</spring_stiffness>
        </dynamics>
      </axis>
    </joint>
    <link name='chessaton_hand_tcp_yaw'>
      <pose relative_to='chessaton_hand_tcp_yaw_virtual_joint'>0 0 0 0 0 0</pose>
      <inertial>
        <pose>0.011394 -0.0086324 -0.005 0 0 0</pose>
        <mass>0.017600000000000001</mass>
        <inertia>
          <ixx>1.21292e-06</ixx>
          <ixy>-2.8281999999999999e-07</ixy>
          <ixz>2.3293406049493259e-21</ixz>
          <iyy>1.8079399999999999e-06</iyy>
          <iyz>1.482307657695026e-21</iyz>
          <izz>1.68754e-06</izz>
        </inertia>
      </inertial>
      <self_collide>false</self_collide>
    </link>
    <joint name='left_finger_joint' type='prismatic'>
      <pose relative_to='chessaton_link4'>0.070608507146197 -0.0126359232516508 -0.0087074752469517 0 0 0</pose>
      <parent>chessaton_link4</parent>
      <child>left_finger</child>
      <axis>
        <xyz>0 1 0</xyz>
        <limit>
          <lower>0</lower>
          <upper>0.023</upper>
          <effort>100</effort>
          <velocity>0.01</velocity>
        </limit>
        <dynamics>
          <damping>1</damping>
          <friction>1</friction>
          <spring_reference>0</spring_reference>
          <spring_stiffness>0</spring_stiffness>
        </dynamics>
      </axis>
    </joint>
    <link name='left_finger'>
      <pose relative_to='left_finger_joint'>0 0 0 0 0 0</pose>
      <inertial>
        <pose>0.012703 0.0015457 0.0030231 0 0 0</pose>
        <mass>0.0060000000000000001</mass>
        <inertia>
          <ixx>8.3567000000000002e-07</ixx>
          <ixy>-1.3337000000000001e-07</ixy>
          <ixz>1.7186999999999999e-07</ixz>
          <iyy>1.1252e-06</iyy>
          <iyz>1.949e-07</iyz>
          <izz>1.5628000000000001e-06</izz>
        </inertia>
      </inertial>
      <collision name='left_finger_collision'>
        <pose>0 0 0 0 0 0</pose>
        <geometry>
          <mesh>
            <scale>1 1 1</scale>
            <uri>file:///home/ros/workspace/install/chessaton_description/share/chessaton_description/meshes/left_finger.STL</uri>
          </mesh>
        </geometry>
        <surface>
          <contact>
            <ode>
              <kp>1000000</kp>
              <kd>1</kd>
              <min_depth>0.001</min_depth>
            </ode>
          </contact>
          <friction>
            <ode>
              <mu>1.1499999999999999</mu>
              <mu2>1.1499999999999999</mu2>
            </ode>
          </friction>
        </surface>
      </collision>
      <visual name='left_finger_visual'>
        <pose>0 0 0 0 0 0</pose>
        <geometry>
          <mesh>
            <scale>1 1 1</scale>
            <uri>file:///home/ros/workspace/install/chessaton_description/share/chessaton_description/meshes/left_finger.STL</uri>
          </mesh>
        </geometry>
        <material>
          <script>
            <name>Gazebo/Grey</name>
            <uri>file://media/materials/scripts/gazebo.material</uri>
          </script>
          <diffuse>0.990196 1 1 1</diffuse>
          <ambient>0.990196 1 1 1</ambient>
        </material>
      </visual>
      <self_collide>false</self_collide>
    </link>
    <joint name='right_finger_joint' type='prismatic'>
      <pose relative_to='chessaton_link4'>0.070608507146197 -0.0126359232516508 -0.0087074752469517 0 0 0</pose>
      <parent>chessaton_link4</parent>
      <child>right_finger</child>
      <axis>
        <xyz>0 1 0</xyz>
        <limit>
          <lower>-0.023</lower>
          <upper>0</upper>
          <effort>100</effort>
          <velocity>0.01</velocity>
        </limit>
        <dynamics>
          <damping>1</damping>
          <friction>1</friction>
          <spring_reference>0</spring_reference>
          <spring_stiffness>0</spring_stiffness>
        </dynamics>
      </axis>
    </joint>
    <link name='right_finger'>
      <pose relative_to='right_finger_joint'>0 0 0 0 0 0</pose>
      <inertial>
        <pose>0.012704 -0.0015462 -0.0030231 0 0 0</pose>
        <mass>0.0060000000000000001</mass>
        <inertia>
          <ixx>8.357e-07</ixx>
          <ixy>1.3337000000000001e-07</ixy>
          <ixz>-1.7186e-07</ixz>
          <iyy>1.1252e-06</iyy>
          <iyz>1.9490999999999999e-07</iyz>
          <izz>1.5629000000000001e-06</izz>
        </inertia>
      </inertial>
      <collision name='right_finger_collision'>
        <pose>0 0 0 0 0 0</pose>
        <geometry>
          <mesh>
            <scale>1 1 1</scale>
            <uri>file:///home/ros/workspace/install/chessaton_description/share/chessaton_description/meshes/right_finger.STL</uri>
          </mesh>
        </geometry>
        <surface>
          <contact>
            <ode>
              <kp>1000000</kp>
              <kd>1</kd>
              <min_depth>0.001</min_depth>
            </ode>
          </contact>
          <friction>
            <ode>
              <mu>1.1499999999999999</mu>
              <mu2>1.1499999999999999</mu2>
            </ode>
          </friction>
        </surface>
      </collision>
      <visual name='right_finger_visual'>
        <pose>0 0 0 0 0 0</pose>
        <geometry>
          <mesh>
            <scale>1 1 1</scale>
            <uri>file:///home/ros/workspace/install/chessaton_description/share/chessaton_description/meshes/right_finger.STL</uri>
          </mesh>
        </geometry>
        <material>
          <script>
            <name>Gazebo/Grey</name>
            <uri>file://media/materials/scripts/gazebo.material</uri>
          </script>
          <diffuse>0.9902 1 1 1</diffuse>
          <ambient>0.9902 1 1 1</ambient>
        </material>
      </visual>
      <self_collide>false</self_collide>
    </link>
    <plugin name='gazebo_grasp_fix' filename='libgazebo_grasp_fix.so'>
      <arm>
        <arm_name>chessaton</arm_name>
        <palm_link>chessaton_link4</palm_link>
        <gripper_link>right_finger</gripper_link>
        <gripper_link>left_finger</gripper_link>
      </arm>
      <forces_angle_tolerance>165</forces_angle_tolerance>
      <update_rate>60</update_rate>
      <grip_count_threshold>1</grip_count_threshold>
      <max_grip_count>20</max_grip_count>
      <release_tolerance>0.0004</release_tolerance>
      <disable_collisions_on_attach>false</disable_collisions_on_attach>
      <contact_topic>__default_topic__</contact_topic>
    </plugin>
    <plugin name='gazebo_ros2_control' filename='libgazebo_ros2_control.so'>
      <parameters>/home/ros/workspace/install/chessaton_description/share/chessaton_description/config/controllers_position.yaml</parameters>
    </plugin>
    <frame name='gripper_joint' attached_to='chessaton_link4'>
      <pose>0.070609 -0.012636 -0.008707 0 -0 0</pose>
    </frame>
    <frame name='chessaton_gripper' attached_to='gripper_joint'/>
    <frame name='chessaton_hand_tcp_virtual_joint' attached_to='chessaton_hand_tcp_yaw'>
      <pose>0 0 0 0 -0 0</pose>
    </frame>
    <frame name='chessaton_hand_tcp' attached_to='chessaton_hand_tcp_virtual_joint'/>
  </model>
</sdf>
