<sdf version='1.9'>
  <model name='chessaton'>
    <joint name='virtual_joint' type='fixed'>
      <pose relative_to='__model__'>0 0 0 0 0 0</pose>
      <parent>world</parent>
      <child>chessaton_link0</child>
    </joint>
    <link name='chessaton_link0'>
      <pose relative_to='virtual_joint'>0 0 0 0 0 0</pose>
      <inertial>
        <pose>-0.050129 -0.010271 0.035819 0 0 0</pose>
        <mass>0.17446999999999999</mass>
        <inertia>
          <ixx>0.00011969</ixx>
          <ixy>1.6753e-09</ixy>
          <ixz>4.5327999999999999e-07</ixz>
          <iyy>0.00034675</iyy>
          <iyz>-4.0946000000000003e-09</iyz>
          <izz>0.00045331000000000001</izz>
        </inertia>
      </inertial>
      <collision name='chessaton_link0_collision'>
        <pose>0 0 0 0 0 0</pose>
        <geometry>
          <mesh>
            <scale>1 1 1</scale>
            <uri>file:///home/ros/workspace/install/chessaton_description/share/chessaton_description/meshes/chessaton_link0.STL</uri>
          </mesh>
        </geometry>
        <surface>
          <contact>
            <ode>
              <kp>1000000</kp>
              <kd>1</kd>
            </ode>
          </contact>
          <friction>
            <ode>
              <mu>0.84999999999999998</mu>
              <mu2>0.84999999999999998</mu2>
            </ode>
          </friction>
        </surface>
      </collision>
      <visual name='chessaton_link0_visual'>
        <pose>0 0 0 0 0 0</pose>
        <geometry>
          <mesh>
            <scale>1 1 1</scale>
            <uri>file:///home/ros/workspace/install/chessaton_description/share/chessaton_description/meshes/chessaton_link0.STL</uri>
          </mesh>
        </geometry>
        <material>
          <script>
            <name>Gazebo/Green</name>
            <uri>file://media/materials/scripts/gazebo.material</uri>
          </script>
          <diffuse>1 1 1 1</diffuse>
          <ambient>1 1 1 1</ambient>
        </material>
      </visual>
      <self_collide>false</self_collide>
    </link>
    <joint name='chessaton_joint1' type='revolute'>
      <pose relative_to='chessaton_link0'>0 0 0.08094 0 0 0</pose>
      <parent>chessaton_link0</parent>
      <child>chessaton_link1</child>
      <axis>
        <xyz>0 0 -1</xyz>
        <limit>
          <lower>-1.570796326794897</lower>
          <upper>1.570796326794897</upper>
          <effort>0</effort>
          <velocity>5</velocity>
        </limit>
        <dynamics>
          <damping>0.5</damping>
          <friction>0</friction>
          <spring_reference>0</spring_reference>
          <spring_stiffness>0</spring_stiffness>
        </dynamics>
      </axis>
    </joint>
    <link name='chessaton_link1'>
      <pose relative_to='chessaton_joint1'>0 0 0 0 0 0</pose>
      <inertial>
        <pose>0.012052 -0.0041948 0.012838 0 0 0</pose>
        <mass>0.046510999999999997</mass>
        <inertia>
          <ixx>7.7123000000000007e-06</ixx>
          <ixy>-4.0765999999999998e-09</ixy>
          <ixz>1.6732e-09</ixz>
          <iyy>1.046e-05</iyy>
          <iyz>4.5326999999999998e-07</iyz>
          <izz>1.4406999999999999e-05</izz>
        </inertia>
      </inertial>
      <collision name='chessaton_link1_collision'>
        <pose>0 0 0 0 0 0</pose>
        <geometry>
          <mesh>
            <scale>1 1 1</scale>
            <uri>file:///home/ros/workspace/install/chessaton_description/share/chessaton_description/meshes/chessaton_link1.STL</uri>
          </mesh>
        </geometry>
        <surface>
          <contact>
            <ode>
              <kp>1000000</kp>
              <kd>1</kd>
            </ode>
          </contact>
          <friction>
            <ode>
              <mu>0.84999999999999998</mu>
              <mu2>0.84999999999999998</mu2>
            </ode>
          </friction>
        </surface>
      </collision>
      <visual name='chessaton_link1_visual'>
        <pose>0 0 0 0 0 0</pose>
        <geometry>
          <mesh>
            <scale>1 1 1</scale>
            <uri>file:///home/ros/workspace/install/chessaton_description/share/chessaton_description/meshes/chessaton_link1.STL</uri>
          </mesh>
        </geometry>
        <material>
          <script>
            <name>Gazebo/Blue</name>
            <uri>file://media/materials/scripts/gazebo.material</uri>
          </script>
          <diffuse>0.62255 0.62255 0.62255 1</diffuse>
          <ambient>0.62255 0.62255 0.62255 1</ambient>
        </material>
      </visual>
      <self_collide>false</self_collide>
    </link>
    <joint name='chessaton_joint2' type='revolute'>
      <pose relative_to='chessaton_link1'>0.022104 0.022723 0.015309 0 0 0</pose>
      <parent>chessaton_link1</parent>
      <child>chessaton_link2</child>
      <axis>
        <xyz>0 -1 0</xyz>
        <limit>
          <lower>-1.570796326794897</lower>
          <upper>1.570796326794897</upper>
          <effort>0</effort>
          <velocity>5</velocity>
        </limit>
        <dynamics>
          <damping>0.5</damping>
          <friction>0</friction>
          <spring_reference>0</spring_reference>
          <spring_stiffness>0</spring_stiffness>
        </dynamics>
      </axis>
    </joint>
    <link name='chessaton_link2'>
      <pose relative_to='chessaton_joint2'>0 0 0 0 0 0</pose>
      <inertial>
        <pose>-6.8198e-09 -0.0253 0.093503 0 0 0</pose>
        <mass>0.070955000000000004</mass>
        <inertia>
          <ixx>6.1321000000000005e-05</ixx>
          <ixy>7.7896999999999994e-20</ixy>
          <ixz>4.4464000000000001e-12</ixz>
          <iyy>3.6390000000000002e-05</iyy>
          <iyz>-5.6970999999999997e-19</iyz>
          <izz>3.1035999999999999e-05</izz>
        </inertia>
      </inertial>
      <collision name='chessaton_link2_collision'>
        <pose>0 0 0 0 0 0</pose>
        <geometry>
          <mesh>
            <scale>1 1 1</scale>
            <uri>file:///home/ros/workspace/install/chessaton_description/share/chessaton_description/meshes/chessaton_link2.STL</uri>
          </mesh>
        </geometry>
        <surface>
          <contact>
            <ode>
              <kp>1000000</kp>
              <kd>1</kd>
            </ode>
          </contact>
          <friction>
            <ode>
              <mu>0.84999999999999998</mu>
              <mu2>0.84999999999999998</mu2>
            </ode>
          </friction>
        </surface>
      </collision>
      <visual name='chessaton_link2_visual'>
        <pose>0 0 0 0 0 0</pose>
        <geometry>
          <mesh>
            <scale>1 1 1</scale>
            <uri>file:///home/ros/workspace/install/chessaton_description/share/chessaton_description/meshes/chessaton_link2.STL</uri>
          </mesh>
        </geometry>
        <material>
          <script>
            <name>Gazebo/Orange</name>
            <uri>file://media/materials/scripts/gazebo.material</uri>
          </script>
          <diffuse>0.941176 0.941176 0.941176 1</diffuse>
          <ambient>0.941176 0.941176 0.941176 1</ambient>
        </material>
      </visual>
      <self_collide>false</self_collide>
    </link>
    <joint name='chessaton_joint3' type='revolute'>
      <pose relative_to='chessaton_link2'>0 0 0.18701 0 0 0</pose>
      <parent>chessaton_link2</parent>
      <child>chessaton_link3</child>
      <axis>
        <xyz>0 -1 0</xyz>
        <limit>
          <lower>-1.570796326794897</lower>
          <upper>1.570796326794897</upper>
          <effort>0</effort>
          <velocity>6</velocity>
        </limit>
        <dynamics>
          <damping>0.5</damping>
          <friction>0</friction>
          <spring_reference>0</spring_reference>
          <spring_stiffness>0</spring_stiffness>
        </dynamics>
      </axis>
    </joint>
    <link name='chessaton_link3'>
      <pose relative_to='chessaton_joint3'>0 0 0 0 0 0</pose>
      <inertial>
        <pose>0.061953 -0.024546 -0.0017072 0 0 0</pose>
        <mass>0.099802000000000002</mass>
        <inertia>
          <ixx>2.455e-05</ixx>
          <ixy>6.6798e-10</ixy>
          <ixz>-2.7683000000000002e-07</ixz>
          <iyy>3.4978000000000003e-05</iyy>
          <iyz>4.5265000000000002e-07</iyz>
          <izz>5.1335000000000002e-05</izz>
        </inertia>
      </inertial>
      <collision name='chessaton_link3_collision'>
        <pose>0 0 0 0 0 0</pose>
        <geometry>
          <mesh>
            <scale>1 1 1</scale>
            <uri>file:///home/ros/workspace/install/chessaton_description/share/chessaton_description/meshes/chessaton_link3.STL</uri>
          </mesh>
        </geometry>
        <surface>
          <contact>
            <ode>
              <kp>1000000</kp>
              <kd>1</kd>
            </ode>
          </contact>
          <friction>
            <ode>
              <mu>0.84999999999999998</mu>
              <mu2>0.84999999999999998</mu2>
            </ode>
          </friction>
        </surface>
      </collision>
      <visual name='chessaton_link3_visual'>
        <pose>0 0 0 0 0 0</pose>
        <geometry>
          <mesh>
            <scale>1 1 1</scale>
            <uri>file:///home/ros/workspace/install/chessaton_description/share/chessaton_description/meshes/chessaton_link3.STL</uri>
          </mesh>
        </geometry>
        <material>
          <script>
            <name>Gazebo/Red</name>
            <uri>file://media/materials/scripts/gazebo.material</uri>
          </script>
          <diffuse>0.941176 0.941176 0.941176 1</diffuse>
          <ambient>0.941176 0.941176 0.941176 1</ambient>
        </material>
      </visual>
      <self_collide>false</self_collide>
    </link>
    <joint name='chessaton_joint4' type='revolute'>
      <pose relative_to='chessaton_link3'>0.17811 0.0028273 9.1141e-05 0 0 0</pose>
      <parent>chessaton_link3</parent>
      <child>chessaton_link4</child>
      <axis>
        <xyz>0 -1 0</xyz>
        <limit>
          <lower>-1.570796326794897</lower>
          <upper>1.570796326794897</upper>
          <effort>0</effort>
          <velocity>6</velocity>
        </limit>
        <dynamics>
          <damping>0.5</damping>
          <friction>0</friction>
          <spring_reference>0</spring_reference>
          <spring_stiffness>0</spring_stiffness>
        </dynamics>
      </axis>
    </joint>
    <link name='chessaton_link4'>
      <pose relative_to='chessaton_joint4'>0 0 0 0 0 0</pose>
      <inertial>
        <pose>0.02677970391123109 -0.03551016874070208 -0.01030187534848121 0 0 0</pose>
        <mass>0.11249254199351739</mass>
        <inertia>
          <ixx>3.9703734389478682e-05</ixx>
          <ixy>1.618582359279513e-05</ixy>
          <ixz>9.3468973283239383e-07</ixz>
          <iyy>6.6710706304359661e-05</iyy>
          <iyz>-1.7642518770348599e-07</iyz>
          <izz>8.2760004441052534e-05</izz>
        </inertia>
      </inertial>
      <collision name='chessaton_link4_collision'>
        <pose>0 0 0 0 0 0</pose>
        <geometry>
          <mesh>
            <scale>1 1 1</scale>
            <uri>file:///home/ros/workspace/install/chessaton_description/share/chessaton_description/meshes/chessaton_link4.STL</uri>
          </mesh>
        </geometry>
        <surface>
          <contact>
            <ode>
              <kp>1000000</kp>
              <kd>1</kd>
            </ode>
          </contact>
          <friction>
            <ode>
              <mu>0.84999999999999998</mu>
              <mu2>0.84999999999999998</mu2>
            </ode>
          </friction>
        </surface>
      </collision>
      <collision name='chessaton_link4_fixed_joint_lump__chessaton_gripper_collision_1'>
        <pose>0.07060900000000001 -0.033634 -0.0087075 0 0 0</pose>
        <geometry>
          <mesh>
            <scale>1 1 1</scale>
            <uri>file:///home/ros/workspace/install/chessaton_description/share/chessaton_description/meshes/chessaton_gripper.STL</uri>
          </mesh>
        </geometry>
        <surface>
          <contact>
            <ode>
              <kp>1000000</kp>
              <kd>1</kd>
            </ode>
          </contact>
          <friction>
            <ode>
              <mu>0.84999999999999998</mu>
              <mu2>0.84999999999999998</mu2>
            </ode>
          </friction>
        </surface>
      </collision>
      <visual name='chessaton_link4_visual'>
        <pose>0 0 0 0 0 0</pose>
        <geometry>
          <mesh>
            <scale>1 1 1</scale>
            <uri>file:///home/ros/workspace/install/chessaton_description/share/chessaton_description/meshes/chessaton_link4.STL</uri>
          </mesh>
        </geometry>
        <material>
          <script>
            <name>Gazebo/Black</name>
            <uri>file://media/materials/scripts/gazebo.material</uri>
          </script>
          <diffuse>0.941175 0.941175 0.941175 1</diffuse>
          <ambient>0.941175 0.941175 0.941175 1</ambient>
        </material>
      </visual>
      <visual name='chessaton_link4_fixed_joint_lump__chessaton_gripper_visual_1'>
        <pose>0.07060900000000001 -0.033634 -0.0087075 0 0 0</pose>
        <geometry>
          <mesh>
            <scale>1 1 1</scale>
            <uri>file:///home/ros/workspace/install/chessaton_description/share/chessaton_description/meshes/chessaton_gripper.STL</uri>
          </mesh>
        </geometry>
        <material>
          <script>
            <name>Gazebo/White</name>
            <uri>file://media/materials/scripts/gazebo.material</uri>
          </script>
          <diffuse>0.62255 0.62255 0.62255 1</diffuse>
          <ambient>0.62255 0.62255 0.62255 1</ambient>
        </material>
      </visual>
      <self_collide>false</self_collide>
    </link>
    <joint name='chessaton_hand_tcp_roll_virtual_joint' type='revolute'>
      <pose relative_to='chessaton_link4'>0.100609 -0.033634 -0.0087075 0 0 0</pose>
      <parent>chessaton_link4</parent>
      <child>chessaton_hand_tcp_roll</child>
      <axis>
        <xyz>-1 0 0</xyz>
        <limit>
          <lower>-1.570796326794897</lower>
          <upper>1.570796326794897</upper>
          <effort>0</effort>
          <velocity>6</velocity>
        </limit>
        <dynamics>
          <damping>1</damping>
          <friction>1</friction>
          <spring_reference>0</spring_reference>
          <spring_stiffness>0</spring_stiffness>
        </dynamics>
      </axis>
    </joint>
    <link name='chessaton_hand_tcp_roll'>
      <pose relative_to='chessaton_hand_tcp_roll_virtual_joint'>0 0 0 0 0 0</pose>
      <inertial>
        <pose>0.011394 -0.0086324 -0.005 0 0 0</pose>
        <mass>0.0088000000000000005</mass>
        <inertia>
          <ixx>6.0645999999999999e-07</ixx>
          <ixy>-1.4140999999999999e-07</ixy>
          <ixz>1.2141999999999999e-21</ixz>
          <iyy>9.0396999999999996e-07</iyy>
          <iyz>7.2150999999999998e-22</iyz>
          <izz>8.4376999999999999e-07</izz>
        </inertia>
      </inertial>
      <self_collide>false</self_collide>
    </link>
    <joint name='chessaton_hand_tcp_yaw_virtual_joint' type='revolute'>
      <pose relative_to='chessaton_hand_tcp_roll'>0 0 0 0 0 0</pose>
      <parent>chessaton_hand_tcp_roll</parent>
      <child>chessaton_hand_tcp_yaw</child>
      <axis>
        <xyz>0 0 -1</xyz>
        <limit>
          <lower>-1.570796326794897</lower>
          <upper>1.570796326794897</upper>
          <effort>0</effort>
          <velocity>6</velocity>
        </limit>
        <dynamics>
          <damping>1</damping>
          <friction>1</friction>
          <spring_reference>0</spring_reference>
          <spring_stiffness>0</spring_stiffness>
        </dynamics>
      </axis>
    </joint>
    <link name='chessaton_hand_tcp_yaw'>
      <pose relative_to='chessaton_hand_tcp_yaw_virtual_joint'>0 0 0 0 0 0</pose>
      <inertial>
        <pose>0.011394 -0.0086324 -0.005 0 0 0</pose>
        <mass>0.0088000000000000005</mass>
        <inertia>
          <ixx>6.0645999999999999e-07</ixx>
          <ixy>-1.4140999999999999e-07</ixy>
          <ixz>1.2141999999999999e-21</ixz>
          <iyy>9.0396999999999996e-07</iyy>
          <iyz>7.2150999999999998e-22</iyz>
          <izz>8.4376999999999999e-07</izz>
        </inertia>
      </inertial>
      <self_collide>false</self_collide>
    </link>
    <joint name='left_finger_joint' type='prismatic'>
      <pose relative_to='chessaton_link4'>0.07060900000000001 -0.033634 -0.0087075 0 0 0</pose>
      <parent>chessaton_link4</parent>
      <child>left_finger</child>
      <axis>
        <xyz>0 1 0</xyz>
        <limit>
          <lower>0</lower>
          <upper>0.023</upper>
          <effort>100</effort>
          <velocity>0.02</velocity>
        </limit>
        <dynamics>
          <damping>1</damping>
          <friction>1</friction>
          <spring_reference>0</spring_reference>
          <spring_stiffness>0</spring_stiffness>
        </dynamics>
      </axis>
    </joint>
    <link name='left_finger'>
      <pose relative_to='left_finger_joint'>0 0 0 0 0 0</pose>
      <inertial>
        <pose>0.0127036998303557 0.00154590778352602 0.00302307598216484 0 0 0</pose>
        <mass>0.0060194543690775797</mass>
        <inertia>
          <ixx>8.3568723730101695e-07</ixx>
          <ixy>-1.3337071782130299e-07</ixy>
          <ixz>1.7186921041133901e-07</ixz>
          <iyy>1.1252098809580501e-06</iyy>
          <iyz>1.9490298685574901e-07</iyz>
          <izz>1.56286387867122e-06</izz>
        </inertia>
      </inertial>
      <collision name='left_finger_collision'>
        <pose>0 0 0 0 0 0</pose>
        <geometry>
          <mesh>
            <scale>1 1 1</scale>
            <uri>file:///home/ros/workspace/install/chessaton_description/share/chessaton_description/meshes/left_finger.STL</uri>
          </mesh>
        </geometry>
        <surface>
          <contact>
            <ode>
              <kp>1000000</kp>
              <kd>1</kd>
              <min_depth>0.001</min_depth>
            </ode>
          </contact>
          <friction>
            <ode>
              <mu>1.1499999999999999</mu>
              <mu2>1.1499999999999999</mu2>
            </ode>
          </friction>
        </surface>
      </collision>
      <visual name='left_finger_visual'>
        <pose>0 0 0 0 0 0</pose>
        <geometry>
          <mesh>
            <scale>1 1 1</scale>
            <uri>file:///home/ros/workspace/install/chessaton_description/share/chessaton_description/meshes/left_finger.STL</uri>
          </mesh>
        </geometry>
        <material>
          <script>
            <name>Gazebo/White</name>
            <uri>file://media/materials/scripts/gazebo.material</uri>
          </script>
          <diffuse>0.990196 1 1 1</diffuse>
          <ambient>0.990196 1 1 1</ambient>
        </material>
      </visual>
      <self_collide>false</self_collide>
    </link>
    <joint name='right_finger_joint' type='prismatic'>
      <pose relative_to='chessaton_link4'>0.07060900000000001 -0.033634 -0.0087075 0 0 0</pose>
      <parent>chessaton_link4</parent>
      <child>right_finger</child>
      <axis>
        <xyz>0 1 0</xyz>
        <limit>
          <lower>-0.023</lower>
          <upper>0</upper>
          <effort>100</effort>
          <velocity>0.02</velocity>
        </limit>
        <dynamics>
          <damping>1</damping>
          <friction>1</friction>
          <spring_reference>0</spring_reference>
          <spring_stiffness>0</spring_stiffness>
        </dynamics>
      </axis>
    </joint>
    <link name='right_finger'>
      <pose relative_to='right_finger_joint'>0 0 0 0 0 0</pose>
      <inertial>
        <pose>0.0127036998303559 -0.00154590852707946 -0.00302307586801259 0 0 0</pose>
        <mass>0.0060194543690774999</mass>
        <inertia>
          <ixx>8.3568723730101399e-07</ixx>
          <ixy>1.3337071782130799e-07</ixy>
          <ixz>-1.71869210411315e-07</ixz>
          <iyy>1.12520988095806e-06</iyy>
          <iyz>1.9490298685577e-07</iyz>
          <izz>1.5628638786712001e-06</izz>
        </inertia>
      </inertial>
      <collision name='right_finger_collision'>
        <pose>0 0 0 0 0 0</pose>
        <geometry>
          <mesh>
            <scale>1 1 1</scale>
            <uri>file:///home/ros/workspace/install/chessaton_description/share/chessaton_description/meshes/right_finger.STL</uri>
          </mesh>
        </geometry>
        <surface>
          <contact>
            <ode>
              <kp>1000000</kp>
              <kd>1</kd>
              <min_depth>0.001</min_depth>
            </ode>
          </contact>
          <friction>
            <ode>
              <mu>1.1499999999999999</mu>
              <mu2>1.1499999999999999</mu2>
            </ode>
          </friction>
        </surface>
      </collision>
      <visual name='right_finger_visual'>
        <pose>0 0 0 0 0 0</pose>
        <geometry>
          <mesh>
            <scale>1 1 1</scale>
            <uri>file:///home/ros/workspace/install/chessaton_description/share/chessaton_description/meshes/right_finger.STL</uri>
          </mesh>
        </geometry>
        <material>
          <script>
            <name>Gazebo/White</name>
            <uri>file://media/materials/scripts/gazebo.material</uri>
          </script>
          <diffuse>0.9902 1 1 1</diffuse>
          <ambient>0.9902 1 1 1</ambient>
        </material>
      </visual>
      <self_collide>false</self_collide>
    </link>
    <plugin name='gazebo_grasp_fix' filename='libgazebo_grasp_fix.so'>
      <arm>
        <arm_name>chessaton</arm_name>
        <palm_link>chessaton_link4</palm_link>
        <gripper_link>right_finger</gripper_link>
        <gripper_link>left_finger</gripper_link>
      </arm>
      <forces_angle_tolerance>140</forces_angle_tolerance>
      <update_rate>30</update_rate>
      <grip_count_threshold>4</grip_count_threshold>
      <max_grip_count>20</max_grip_count>
      <release_tolerance>0.00025</release_tolerance>
      <disable_collisions_on_attach>false</disable_collisions_on_attach>
      <contact_topic>__default_topic__</contact_topic>
    </plugin>
    <plugin name='gazebo_ros2_control' filename='libgazebo_ros2_control.so'>
      <parameters>/home/ros/workspace/install/chessaton_description/share/chessaton_description/config/controllers_position.yaml</parameters>
    </plugin>
    <frame name='gripper_joint' attached_to='chessaton_link4'>
      <pose>0.070609 -0.033634 -0.008708 0 -0 0</pose>
    </frame>
    <frame name='chessaton_gripper' attached_to='gripper_joint'/>
    <frame name='chessaton_hand_tcp_virtual_joint' attached_to='chessaton_hand_tcp_yaw'>
      <pose>0 0 0 0 -0 0</pose>
    </frame>
    <frame name='chessaton_hand_tcp' attached_to='chessaton_hand_tcp_virtual_joint'/>
  </model>
</sdf>
