<?xml version="1.0" ?>
<!-- =================================================================================== -->
<!-- |    This document was autogenerated by xacro from /home/ros/workspace/src/chessaton/chessaton_description/urdf/chessaton.urdf.xacro | -->
<!-- |    EDITING THIS FILE BY HAND IS NOT RECOMMENDED                                 | -->
<!-- =================================================================================== -->
<robot name="chessaton" xmlns:controller="http://playerstage.sourceforge.net/gazebo/xmlschema/#controller" xmlns:interface="http://playerstage.sourceforge.net/gazebo/xmlschema/#interface" xmlns:sensor="http://playerstage.sourceforge.net/gazebo/xmlschema/#sensor">
  <!-- Specify some colours -->
  <material name="metal">
    <color rgba="0.79216 0.81961 0.93333 1"/>
  </material>
  <material name="white">
    <color rgba="1 1 1 1"/>
  </material>
  <material name="orange">
    <color rgba="1 0.3 0.1 1"/>
  </material>
  <material name="blue">
    <color rgba="0.2 0.2 1 1"/>
  </material>
  <material name="color_link0">
    <color rgba="0.89804 0.91765 0.92941 1"/>
  </material>
  <material name="color_link1">
    <color rgba="0.49804 0.49804 0.49804 1"/>
  </material>
  <material name="color_link2">
    <color rgba="0.752941176470588 0.752941176470588 0.752941176470588 1"/>
  </material>
  <material name="color_link3">
    <color rgba="0.752941176470588 0.752941176470588 0.752941176470588 1"/>
  </material>
  <material name="color_link4">
    <color rgba="0.75294 0.75294 0.75294 1"/>
  </material>
  <material name="color_gripper">
    <color rgba="0.49804 0.49804 0.49804 1"/>
  </material>
  <material name="color_gripper_lfinger">
    <color rgba="0.792156862745098 0.819607843137255 0.933333333333333 1"/>
  </material>
  <material name="color_gripper_rfinger">
    <color rgba="0.79216 0.81961 0.93333 1"/>
  </material>
  <!-- Gazebo is unable to use the same <material> tags that are already in the URDF (that RViz uses). -->
  <!-- Instead, we need to add gazebo tags for our links that refer to Gazebo materials -->
  <gazebo reference="chessaton_link0">
    <mu1 value="0.85"/>
    <mu2 value="0.85"/>
    <kp value="1000000.0"/>
    <kd value="1.0"/>
    <material>Gazebo/Green</material>
  </gazebo>
  <gazebo reference="chessaton_link1">
    <mu1 value="0.85"/>
    <mu2 value="0.85"/>
    <kp value="1000000.0"/>
    <kd value="1.0"/>
    <material>Gazebo/Blue</material>
  </gazebo>
  <gazebo reference="chessaton_link2">
    <mu1 value="0.85"/>
    <mu2 value="0.85"/>
    <kp value="1000000.0"/>
    <kd value="1.0"/>
    <material>Gazebo/Orange</material>
  </gazebo>
  <gazebo reference="chessaton_link3">
    <mu1 value="0.85"/>
    <mu2 value="0.85"/>
    <kp value="1000000.0"/>
    <kd value="1.0"/>
    <material>Gazebo/Red</material>
  </gazebo>
  <gazebo reference="chessaton_link4">
    <mu1 value="0.85"/>
    <mu2 value="0.85"/>
    <kp value="1000000.0"/>
    <kd value="1.0"/>
    <material>Gazebo/Black</material>
  </gazebo>
  <gazebo reference="chessaton_gripper">
    <mu1 value="0.85"/>
    <mu2 value="0.85"/>
    <kp value="1000000.0"/>
    <kd value="1.0"/>
    <material>Gazebo/White</material>
  </gazebo>
  <gazebo reference="left_finger">
    <mu1 value="1.15"/>
    <mu2 value="1.15"/>
    <kp value="1000000.0"/>
    <kd value="1.0"/>
    <minDepth>0.001</minDepth>
    <material>Gazebo/White</material>
  </gazebo>
  <gazebo reference="right_finger">
    <mu1 value="1.15"/>
    <mu2 value="1.15"/>
    <kp value="1000000.0"/>
    <kd value="1.0"/>
    <minDepth>0.001</minDepth>
    <material>Gazebo/White</material>
  </gazebo>
  <!-- <gazebo reference="[joint name]">
        <implicitSpringDamper>1</implicitSpringDamper>
    </gazebo> -->
  <gazebo>
    <plugin filename="libgazebo_grasp_fix.so" name="gazebo_grasp_fix">
      <arm>
        <arm_name>chessaton</arm_name>
        <palm_link> chessaton_link4  </palm_link>
        <gripper_link> right_finger </gripper_link>
        <gripper_link> left_finger </gripper_link>
      </arm>
      <forces_angle_tolerance>120</forces_angle_tolerance>
      <update_rate>30</update_rate>
      <grip_count_threshold>4</grip_count_threshold>
      <max_grip_count>20</max_grip_count>
      <release_tolerance>0.00025</release_tolerance>
      <disable_collisions_on_attach>false</disable_collisions_on_attach>
      <contact_topic>__default_topic__</contact_topic>
    </plugin>
  </gazebo>
  <!-- Add a gazebo tag for the ORIGINAL camera_link (but in the plugin we reference the optical frame so that ROS can orient things correctly) -->
  <!-- Within the gazebo tag we have the sensor tag, and inside that there is (among other things) the camera tag with the camera parameters, 
            and the plugin tag with some extra parameters the plugin needs. -->
  <!-- Note that although visualise is set to true, it won't actually visualise the depth camera in gazebo. To see the preview, 
            try swapping "depth" to "camera"-->
  <gazebo reference="camera_link">
    <sensor name="my_camera" type="depth">
      <always_on>true</always_on>
      <update_rate>20</update_rate>
      <visualize>true</visualize>
      <camera name="cam">
        <!-- <horizontal_fov>1.3962634</horizontal_fov> -->
        <horizontal_fov>1.0471975511965976</horizontal_fov>
        <image>
          <width>640</width>
          <height>480</height>
          <format>B8G8R8</format>
        </image>
        <clip>
          <near>0.05</near>
          <far>8</far>
        </clip>
        <noise>
          <type>gaussian</type>
          <mean>0.0</mean>
          <stddev>0.007</stddev>
        </noise>
      </camera>
      <plugin filename="libgazebo_ros_camera.so" name="camera_controller">
        <frame_name>camera_link_optical</frame_name>
        <min_depth>0.05</min_depth>
        <max_depth>8</max_depth>
        <baseline>0.1</baseline>
        <alwaysOn>true</alwaysOn>
        <updateRate>10</updateRate>
        <imageTopicName>rgb/image_raw</imageTopicName>
        <cameraInfoTopicName>rgb/camera_info</cameraInfoTopicName>
        <depthImageTopicName>depth/image_raw</depthImageTopicName>
        <depthImageCameraInfoTopicName>depth/camera_info</depthImageCameraInfoTopicName>
        <pointCloudTopicName>depth/points</pointCloudTopicName>
        <pointCloudCutoff>0.3</pointCloudCutoff>
        <distortion_k1>0.0</distortion_k1>
        <distortion_k2>0.0</distortion_k2>
        <distortion_k3>0.0</distortion_k3>
        <distortion_t1>0.0</distortion_t1>
        <distortion_t2>0.0</distortion_t2>
      </plugin>
    </sensor>
  </gazebo>
  <link name="world"/>
  <joint name="virtual_joint" type="fixed">
    <origin rpy="0 0 0" xyz="0 0 0"/>
    <parent link="world"/>
    <child link="chessaton_link0"/>
  </joint>
  <link name="chessaton_link0">
    <visual>
      <origin rpy="0 0 0" xyz="0 0 0"/>
      <geometry>
        <mesh filename="file:///home/ros/workspace/install/chessaton_description/share/chessaton_description/meshes/chessaton_link0.STL"/>
      </geometry>
      <material name="color_link0"/>
    </visual>
    <collision>
      <origin rpy="0 0 0" xyz="0 0 0"/>
      <geometry>
        <mesh filename="file:///home/ros/workspace/install/chessaton_description/share/chessaton_description/meshes/chessaton_link0.STL"/>
      </geometry>
    </collision>
    <inertial>
      <origin rpy="0 0 0" xyz="-0.00073528 0.0040282 0.031188"/>
      <mass value="0.094842"/>
      <inertia ixx="3.0463E-05" ixy="-6.3087E-09" ixz="4.236E-07" iyy="4.8143E-05" iyz="-8.1925E-08" izz="5.1511E-05"/>
    </inertial>
  </link>
  <joint name="chessaton_joint1" type="revolute">
    <origin rpy="0 0 0" xyz="0.00015368 0.01229 0.07705"/>
    <parent link="chessaton_link0"/>
    <child link="chessaton_link1"/>
    <axis xyz="0 0 -1"/>
    <dynamics damping="1.0" friction="1.0"/>
    <limit effort="0" lower="-3.141592653589793" upper="3.141592653589793" velocity="5"/>
  </joint>
  <link name="chessaton_link1">
    <visual>
      <origin rpy="0 0 0" xyz="0 0 0"/>
      <geometry>
        <mesh filename="file:///home/ros/workspace/install/chessaton_description/share/chessaton_description/meshes/chessaton_link1.STL"/>
      </geometry>
      <material name="color_link1"/>
    </visual>
    <collision>
      <origin rpy="0 0 0" xyz="0 0 0"/>
      <geometry>
        <mesh filename="file:///home/ros/workspace/install/chessaton_description/share/chessaton_description/meshes/chessaton_link1.STL"/>
      </geometry>
    </collision>
    <inertial>
      <origin rpy="0 0 0" xyz="0.012256 -0.0045169 0.011915"/>
      <mass value="0.047535"/>
      <inertia ixx="8.1555E-06" ixy="-8.4986E-08" ixz="1.6429E-09" iyy="1.0365E-05" iyz="4.236E-07" izz="1.4637E-05"/>
    </inertial>
  </link>
  <joint name="chessaton_joint2" type="revolute">
    <origin rpy="0 0 0" xyz="0.022504 0.022833 0.013792"/>
    <parent link="chessaton_link1"/>
    <child link="chessaton_link2"/>
    <axis xyz="0 -1 0"/>
    <dynamics damping="1.0" friction="1.0"/>
    <limit effort="0" lower="-1.5707963267948966" upper="1.5707963267948966" velocity="5"/>
  </joint>
  <link name="chessaton_link2">
    <visual>
      <origin rpy="0 0 0" xyz="0 0 0"/>
      <geometry>
        <mesh filename="file:///home/ros/workspace/install/chessaton_description/share/chessaton_description/meshes/chessaton_link2.STL"/>
      </geometry>
      <material name="color_link2"/>
    </visual>
    <inertial>
      <origin rpy="0 0 0" xyz="1.1343E-09 -0.02475 0.101"/>
      <mass value="0.077067"/>
      <inertia ixx="7.2952E-05" ixy="4.5829E-12" ixz="1.1087E-14" iyy="4.7593E-05" iyz="3.7988E-20" izz="3.1748E-05"/>
    </inertial>
    <collision>
      <origin rpy="0 0 0" xyz="0 0 0"/>
      <geometry>
        <mesh filename="file:///home/ros/workspace/install/chessaton_description/share/chessaton_description/meshes/chessaton_link2.STL"/>
      </geometry>
    </collision>
  </link>
  <joint name="chessaton_joint3" type="revolute">
    <origin rpy="0 0 0" xyz="0 0 0.202"/>
    <parent link="chessaton_link2"/>
    <child link="chessaton_link3"/>
    <axis xyz="0 -1 0"/>
    <dynamics damping="1.0" friction="1.0"/>
    <limit effort="0" lower="-1.5707963267948966" upper="1.5707963267948966" velocity="6"/>
  </joint>
  <link name="chessaton_link3">
    <visual>
      <origin rpy="0 0 0" xyz="0 0 0"/>
      <geometry>
        <mesh filename="file:///home/ros/workspace/install/chessaton_description/share/chessaton_description/meshes/chessaton_link3.STL"/>
      </geometry>
      <material name="color_link3"/>
    </visual>
    <collision>
      <origin rpy="0 0 0" xyz="0 0 0"/>
      <geometry>
        <mesh filename="file:///home/ros/workspace/install/chessaton_description/share/chessaton_description/meshes/chessaton_link3.STL"/>
      </geometry>
    </collision>
    <inertial>
      <origin rpy="0 0 0" xyz="0.071008 -0.024827 -0.00025021"/>
      <mass value="0.10766"/>
      <inertia ixx="2.5545E-05" ixy="8.4872E-08" ixz="-3.21E-07" iyy="4.8596E-05" iyz="4.236E-07" izz="6.5475E-05"/>
    </inertial>
  </link>
  <joint name="chessaton_joint4" type="revolute">
    <origin rpy="0 0 0" xyz="0.1985 0.0019174 0.0019578"/>
    <parent link="chessaton_link3"/>
    <child link="chessaton_link4"/>
    <axis xyz="0 -1 0"/>
    <dynamics damping="1.0" friction="1.0"/>
    <limit effort="0" lower="-1.5707963267948966" upper="1.5707963267948966" velocity="6"/>
  </joint>
  <link name="chessaton_link4">
    <visual>
      <origin rpy="0 0 0" xyz="0 0 0"/>
      <geometry>
        <mesh filename="file:///home/ros/workspace/install/chessaton_description/share/chessaton_description/meshes/chessaton_link4.STL"/>
      </geometry>
      <material name="color_link4"/>
    </visual>
    <collision>
      <origin rpy="0 0 0" xyz="0 0 0"/>
      <geometry>
        <mesh filename="file:///home/ros/workspace/install/chessaton_description/share/chessaton_description/meshes/chessaton_link4.STL"/>
      </geometry>
    </collision>
    <inertial>
      <origin rpy="0 0 0" xyz="0.0016488 -0.027436 -0.0097099"/>
      <mass value="0.0466425419935174"/>
      <inertia ixx="1.458E-05" ixy="-4.2359E-07" ixz="-1.6429E-09" iyy="1.0335E-05" iyz="-8.4986E-08" izz="8.1259E-06"/>
    </inertial>
  </link>
  <joint name="gripper_joint" type="fixed">
    <origin rpy="0 0 0" xyz="0.072842 -0.034194 -0.0048547"/>
    <parent link="chessaton_link4"/>
    <child link="chessaton_gripper"/>
    <axis xyz="0 0 0"/>
  </joint>
  <link name="chessaton_gripper">
    <visual>
      <origin rpy="0 0 0" xyz="0 0 0"/>
      <geometry>
        <mesh filename="file:///home/ros/workspace/install/chessaton_description/share/chessaton_description/meshes/chessaton_gripper.STL"/>
      </geometry>
      <material name="color_gripper"/>
    </visual>
    <collision>
      <origin rpy="0 0 0" xyz="0 0 0"/>
      <geometry>
        <mesh filename="file:///home/ros/workspace/install/chessaton_description/share/chessaton_description/meshes/chessaton_gripper.STL"/>
      </geometry>
    </collision>
    <inertial>
      <origin rpy="0 0 0" xyz="-0.027242 0.0063062 -0.003963"/>
      <mass value="0.07416"/>
      <inertia ixx="2.5968E-05" ixy="8.488E-08" ixz="-4.236E-07" iyy="1.3082E-05" iyz="-1.6429E-09" izz="2.6136E-05"/>
    </inertial>
  </link>
  <joint name="left_finger_joint" type="prismatic">
    <origin rpy="0 0 0" xyz="0 0 0"/>
    <parent link="chessaton_gripper"/>
    <child link="left_finger"/>
    <axis xyz="0 1 0"/>
    <dynamics damping="1.0" friction="1.0"/>
    <limit effort="100" lower="0" upper="0.03" velocity="0.02"/>
  </joint>
  <link name="left_finger">
    <visual>
      <origin rpy="0 0 0" xyz="0 0 0"/>
      <geometry>
        <mesh filename="file:///home/ros/workspace/install/chessaton_description/share/chessaton_description/meshes/left_finger.STL"/>
      </geometry>
      <material name="color_gripper_lfinger"/>
    </visual>
    <collision>
      <origin rpy="0 0 0" xyz="0 0 0"/>
      <geometry>
        <mesh filename="file:///home/ros/workspace/install/chessaton_description/share/chessaton_description/meshes/left_finger.STL"/>
      </geometry>
    </collision>
    <inertial>
      <origin rpy="0 0 0" xyz="0.011394 0.0086324 -0.005"/>
      <mass value="0.0088"/>
      <inertia ixx="6.0646E-07" ixy="1.4141E-07" ixz="2.4551E-21" iyy="9.0397E-07" iyz="-6.5992E-22" izz="8.4377E-07"/>
    </inertial>
  </link>
  <joint name="right_finger_joint" type="prismatic">
    <origin rpy="0 0 0" xyz="0 0 0"/>
    <parent link="chessaton_gripper"/>
    <child link="right_finger"/>
    <axis xyz="0 1 0"/>
    <dynamics damping="1.0" friction="1.0"/>
    <limit effort="100" lower="-0.03" upper="0" velocity="0.02"/>
  </joint>
  <link name="right_finger">
    <visual>
      <origin rpy="0 0 0" xyz="0 0 0"/>
      <geometry>
        <mesh filename="file:///home/ros/workspace/install/chessaton_description/share/chessaton_description/meshes/right_finger.STL"/>
      </geometry>
      <material name="color_gripper_rfinger"/>
    </visual>
    <collision>
      <origin rpy="0 0 0" xyz="0 0 0"/>
      <geometry>
        <mesh filename="file:///home/ros/workspace/install/chessaton_description/share/chessaton_description/meshes/right_finger.STL"/>
      </geometry>
    </collision>
    <inertial>
      <origin rpy="0 0 0" xyz="0.011394 -0.0086324 -0.005"/>
      <mass value="0.0088"/>
      <inertia ixx="6.0646E-07" ixy="-1.4141E-07" ixz="1.2142E-21" iyy="9.0397E-07" iyz="7.2151E-22" izz="8.4377E-07"/>
    </inertial>
  </link>
  <joint name="chessaton_hand_tcp_roll_virtual_joint" type="revolute">
    <parent link="chessaton_gripper"/>
    <child link="chessaton_hand_tcp_roll"/>
    <origin rpy="0 0 0" xyz="0.02 0 -0.005"/>
    <axis xyz="-1 0 0"/>
    <dynamics damping="1.0" friction="1.0"/>
    <limit effort="0" lower="-1.5707963267948966" upper="1.5707963267948966" velocity="6"/>
  </joint>
  <link name="chessaton_hand_tcp_roll">
    <inertial>
      <origin rpy="0 0 0" xyz="0.011394 -0.0086324 -0.005"/>
      <mass value="0.0088"/>
      <inertia ixx="6.0646E-07" ixy="-1.4141E-07" ixz="1.2142E-21" iyy="9.0397E-07" iyz="7.2151E-22" izz="8.4377E-07"/>
    </inertial>
  </link>
  <link name="chessaton_hand_tcp_yaw">
    <inertial>
      <origin rpy="0 0 0" xyz="0.011394 -0.0086324 -0.005"/>
      <mass value="0.0088"/>
      <inertia ixx="6.0646E-07" ixy="-1.4141E-07" ixz="1.2142E-21" iyy="9.0397E-07" iyz="7.2151E-22" izz="8.4377E-07"/>
    </inertial>
  </link>
  <joint name="chessaton_hand_tcp_yaw_virtual_joint" type="revolute">
    <parent link="chessaton_hand_tcp_roll"/>
    <child link="chessaton_hand_tcp_yaw"/>
    <origin rpy="0 0 0" xyz="0 0 0"/>
    <axis xyz="0 0 -1"/>
    <dynamics damping="1.0" friction="1.0"/>
    <limit effort="0" lower="-1.5707963267948966" upper="1.5707963267948966" velocity="6"/>
  </joint>
  <link name="chessaton_hand_tcp">
            </link>
  <joint name="chessaton_hand_tcp_virtual_joint" type="fixed">
    <parent link="chessaton_hand_tcp_yaw"/>
    <child link="chessaton_hand_tcp"/>
    <origin rpy="0 0 0" xyz="0 0 0"/>
  </joint>
  <!-- Transmission macro -->
  <!-- <xacro:macro name="SimpleTransmissionPosition" params="joint n">
    <transmission name="tran${n}">
      <type>transmission_interface/SimpleTransmission</type>
      <joint name="${joint}">
        <hardwareInterface>hardware_interface/PositionJointInterface</hardwareInterface>
      </joint>
      <actuator name="motor${n}">
        <mechanicalReduction>1</mechanicalReduction>
      </actuator>
    </transmission>
  </xacro:macro> -->
  <!-- Transmission macro -->
  <!-- <xacro:macro name="SimpleTransmissionEffort" params="joint n">
    <transmission name="tran${n}">
      <type>transmission_interface/SimpleTransmission</type>
      <joint name="${joint}">
        <hardwareInterface>hardware_interface/EffortJointInterface</hardwareInterface>
      </joint>
      <actuator name="motor${n}">
        <mechanicalReduction>1</mechanicalReduction>
      </actuator>
    </transmission>
  </xacro:macro> -->
  <!-- <xacro:SimpleTransmissionEffort n="1" joint="chessaton_joint1" />

  <xacro:SimpleTransmissionEffort n="2" joint="chessaton_joint2" />

  <xacro:SimpleTransmissionEffort n="3" joint="chessaton_joint3" />

  <xacro:SimpleTransmissionEffort n="4" joint="chessaton_joint4" />

  <xacro:SimpleTransmissionEffort n="5" joint="left_finger_joint" />

  <xacro:SimpleTransmissionEffort n="6" joint="right_finger_joint" /> -->
  <gazebo>
    <plugin filename="libgazebo_ros2_control.so" name="gazebo_ros2_control">
      <parameters>/home/ros/workspace/install/chessaton_description/share/chessaton_description/config/controllers_position.yaml</parameters>
    </plugin>
  </gazebo>
  <ros2_control name="GazeboSystem" type="system">
    <hardware>
      <plugin>gazebo_ros2_control/GazeboSystem</plugin>
    </hardware>
    <joint name="chessaton_joint1">
      <command_interface name="position"/>
      <state_interface name="position">
        <param name="initial_value">0.0</param>
      </state_interface>
      <state_interface name="velocity"/>
      <state_interface name="effort"/>
    </joint>
    <joint name="chessaton_joint2">
      <command_interface name="position"/>
      <state_interface name="position">
        <param name="initial_value">0.0</param>
      </state_interface>
      <state_interface name="velocity"/>
      <state_interface name="effort"/>
    </joint>
    <joint name="chessaton_joint3">
      <command_interface name="position"/>
      <state_interface name="position">
        <param name="initial_value">0.0</param>
      </state_interface>
      <state_interface name="velocity"/>
      <state_interface name="effort"/>
    </joint>
    <joint name="chessaton_joint4">
      <command_interface name="position"/>
      <state_interface name="position">
        <param name="initial_value">0.0</param>
      </state_interface>
      <state_interface name="velocity"/>
      <state_interface name="effort"/>
    </joint>
    <joint name="chessaton_hand_tcp_roll_virtual_joint">
      <command_interface name="position"/>
      <state_interface name="position">
        <param name="initial_value">0.0</param>
      </state_interface>
      <state_interface name="velocity"/>
      <state_interface name="effort"/>
    </joint>
    <joint name="chessaton_hand_tcp_yaw_virtual_joint">
      <command_interface name="position"/>
      <state_interface name="position">
        <param name="initial_value">0.0</param>
      </state_interface>
      <state_interface name="velocity"/>
      <state_interface name="effort"/>
    </joint>
    <joint name="left_finger_joint">
      <command_interface name="position"/>
      <state_interface name="position">
        <param name="initial_value">0.0</param>
      </state_interface>
      <state_interface name="velocity"/>
      <state_interface name="effort"/>
    </joint>
    <joint name="right_finger_joint">
      <command_interface name="position"/>
      <state_interface name="position">
        <param name="initial_value">0.0</param>
      </state_interface>
      <state_interface name="velocity"/>
      <state_interface name="effort"/>
    </joint>
  </ros2_control>
  <gazebo reference="chessaton_link0">
    <selfCollide>false</selfCollide>
  </gazebo>
  <gazebo reference="chessaton_link1">
    <selfCollide>false</selfCollide>
  </gazebo>
  <gazebo reference="chessaton_link2">
    <selfCollide>false</selfCollide>
  </gazebo>
  <gazebo reference="chessaton_link3">
    <selfCollide>false</selfCollide>
  </gazebo>
  <gazebo reference="chessaton_link4">
    <selfCollide>false</selfCollide>
  </gazebo>
  <gazebo reference="chessaton_link5">
    <selfCollide>false</selfCollide>
  </gazebo>
  <gazebo reference="chessaton_link6">
    <selfCollide>false</selfCollide>
  </gazebo>
  <gazebo reference="chessaton_hand_tcp_roll">
    <selfCollide>false</selfCollide>
  </gazebo>
  <gazebo reference="chessaton_hand_tcp_yaw">
    <selfCollide>false</selfCollide>
  </gazebo>
  <gazebo reference="chessaton_gripper">
    <selfCollide>false</selfCollide>
  </gazebo>
  <gazebo reference="left_finger">
    <selfCollide>false</selfCollide>
  </gazebo>
  <gazebo reference="right_finger">
    <selfCollide>false</selfCollide>
  </gazebo>
</robot>
