<?xml version="1.0" encoding="utf-8"?>
<robot xmlns:xacro="http://www.ros.org/wiki/xacro" 
    xmlns:sensor="http://playerstage.sourceforge.net/gazebo/xmlschema/#sensor"
    xmlns:controller="http://playerstage.sourceforge.net/gazebo/xmlschema/#controller"
    xmlns:interface="http://playerstage.sourceforge.net/gazebo/xmlschema/#interface"
    name="chessaton">

    <xacro:include filename="$(find chessaton_description)/urdf/chessaton_include.xacro" />
    <xacro:include filename="$(find chessaton_description)/urdf/chessaton_gazebo.xacro" />
    <xacro:include filename="$(find chessaton_description)/urdf/chessaton.ros2_control" />
    <xacro:include filename="$(find chessaton_description)/urdf/chessaton_hand.xacro" />
    <xacro:include filename="$(find chessaton_description)/urdf/sensors/camera.urdf.xacro" />

    <!--            -->
    <!-- Parameters -->
    <!--            -->
    <!-- Name of the robot (mandatory) -->
    <xacro:arg name="name" default="chessaton"/>
    <!-- Prefix for all entities -->
    <xacro:arg name="prefix" default="chessaton_"/>
    <!-- Flag to enable default gripper -->
    <xacro:arg name="gripper" default="true" />
    <xacro:arg name="virtual_dof" default="true" />
    <!-- Flag to enable camera -->
    <xacro:arg name="use_camera" default="false" />
    <!-- ros2_control -->
    <!-- Flag to enable ros2 controllers for manipulator -->
    <xacro:arg name="ros2_control" default="true"/>
    <!-- The ros2_control plugin that should be loaded for the manipulator ('fake', 'gz', 'real' or custom) -->
    <xacro:arg name="ros2_control_plugin" default="gz"/>
    <!-- The output control command interface provided by ros2_control ('position', 'velocity', 'effort' or certain combinations 'position,velocity') -->
    <xacro:arg name="ros2_control_command_interface" default="position"/>
    <!-- The filepath to parameters of ROS 2 controllers -->
    <xacro:arg name="ros2_controller_parameters" default="$(find chessaton_description)/config/controllers_$(arg ros2_control_command_interface).yaml"/>
    <!-- Flag to preserve fixed joints and prevent lumping when generating SDF for Gazebo -->
    <xacro:arg name="gazebo_preserve_fixed_joint" default="false"/>


    <link name="world"></link>

    <joint name="virtual_joint" type="fixed">
        <origin xyz="0 0 0" rpy="0 0 0" />
        <parent link="world" />
        <child link="chessaton_link0" />
    </joint>

    <link name="chessaton_link0">
        <visual>
            <origin xyz="0 0 0" rpy="0 0 0" />
            <geometry>
              <mesh filename="file://$(find chessaton_description)/meshes/chessaton_link0.STL" />
            </geometry>
            <material name="color_link0" />
        </visual>
    
        <collision>
          <origin xyz="0 0 0" rpy="0 0 0" />
          <geometry>
            <mesh filename="file://$(find chessaton_description)/meshes/chessaton_link0.STL" />
          </geometry>
        </collision>

        <inertial>
            <origin xyz="-0.00088323 -3.593E-07 0.021799" rpy="0 0 0" />
            <mass value="0.35099" />
            <inertia
                ixx="0.00040857"
                ixy="-1.2568E-09"
                ixz="-4.0915E-09"
                iyy="0.00041214"
                iyz="1.5948E-10"
                izz="0.00079973" />
        </inertial> 
    </link>

    <joint name="chessaton_joint1" type="revolute">
        <origin xyz="0 0 0.07184" rpy="0 0 0" />
        <parent link="chessaton_link0" />
        <child link="chessaton_link1" />
        <axis xyz="0 0 -1" />
		<dynamics damping="0.01" friction="0.01" />
        <limit lower="${-pi/2}" upper="${pi/2}" effort="0" velocity="0.2618" />
    </joint>

    <link name="chessaton_link1">
        <visual>
          <origin xyz="0 0 0" rpy="0 0 0" />
          <geometry>
            <mesh filename="file://$(find chessaton_description)/meshes/chessaton_link1.STL" />
          </geometry>
          <material name="color_link1" />
        </visual>

        <collision>
          <origin xyz="0 0 0" rpy="0 0 0" />
          <geometry>
            <mesh filename="file://$(find chessaton_description)/meshes/chessaton_link1.STL" />
          </geometry>
        </collision>

        <inertial>
            <origin xyz="-2.48292998257112E-06 1.80948923297683E-11 0.0255783185959284" rpy="0 0 0" />
            <mass value="0.11596191407717" />
            <inertia
              ixx="5.46629273225896E-05"
              ixy="-1.33156669187786E-07"
              ixz="3.35258624200402E-14"
              iyy="4.25165415022482E-05"
              iyz="-8.2983289116076E-14"
              izz="8.94434749602387E-05" />
        </inertial>
    </link>

	<joint name="chessaton_joint2" type="revolute">
		<origin xyz="0 1.2977E-05 0.030569" rpy="0 0 0" />
		<parent link="chessaton_link1" />
		<child link="chessaton_link2" />
		<axis xyz="0 1 0" />
		<dynamics damping="0.01" friction="0.01" />
		<limit lower="${-pi/2}" upper="${pi/2}" effort="0" velocity="0.2618" />
	</joint>

    <link name="chessaton_link2">
        <visual>
            <origin xyz="0 0 0" rpy="0 0 0" />
            <geometry>
              <mesh filename="file://$(find chessaton_description)/meshes/chessaton_link2.STL" />
            </geometry>
            <material name="color_link2" />
        </visual>

        <inertial>
            <origin xyz="-2.3338E-06 4.5723E-05 0.093503" rpy="0 0 0" />
            <mass value="0.070955" />
            <inertia
              ixx="6.1321E-05"
              ixy="-6.9447E-10"
              ixz="4.4166E-12"
              iyy="3.639E-05"
              iyz="-4.4751E-13"
              izz="3.1036E-05" />
        </inertial>

        <collision>
          <origin xyz="0 0 0" rpy="0 0 0" />
          <geometry>
            <mesh filename="file://$(find chessaton_description)/meshes/chessaton_link2.STL" />
          </geometry>
        </collision>
    </link>

	<joint name="chessaton_joint3" type="revolute">
	  	<origin xyz="0 0.025346 0.18701" rpy="0 0 0" />
	  	<parent link="chessaton_link2" />
	  	<child link="chessaton_link3" />
	  	<axis xyz="0 1 0" />
	  	<dynamics damping="0.01" friction="0.01" />
	  	<limit lower="${-pi/2}" upper="${pi/2}" effort="0" velocity="0.2618" />
	</joint>

	<link name="chessaton_link3">
		<visual>
		  <origin xyz="0 0 0" rpy="0 0 0" />
		  <geometry>
		    <mesh filename="file://$(find chessaton_description)/meshes/chessaton_link3.STL" />
		  </geometry>
		  <material name="color_link3" />
		</visual>

		<collision>
		  <origin xyz="0 0 0" rpy="0 0 0" />
		  <geometry>
		    <mesh filename="file://$(find chessaton_description)/meshes/chessaton_link3.STL" />
		  </geometry>
		</collision>

		<inertial>
            <origin xyz="0.0619519890876748 -0.0245474768443102 -0.00170721074679331" rpy="0 0 0" />
            <mass value="0.01" />
            <inertia
              ixx="2.45504457142139E-05"
              ixy="9.48952036737489E-10"
              ixz="-2.76965747257156E-07"
              iyy="3.49778436797956E-05"
              iyz="4.52657683759416E-07"
              izz="5.13350744770814E-05" />
        </inertial>
	</link>

	<joint name="chessaton_joint4" type="revolute">
	    <origin xyz="0.17811 0.0028223 9.1137E-05" rpy="0 0 0" />
	    <parent link="chessaton_link3" />
	    <child link="chessaton_link4" />
	    <axis xyz="0 1 0" />
		<dynamics damping="0.01" friction="0.01" />
	    <limit lower="${-pi/2}" upper="${pi/2}" effort="0" velocity="0.2618" />
	</joint>

	<link name="chessaton_link4">
		<visual>
		  <origin xyz="0 0 0" rpy="0 0 0" />
		  <geometry>
		    <mesh filename="file://$(find chessaton_description)/meshes/chessaton_link4.STL" />
		  </geometry>
		  <material name="color_link4" />
		</visual>

		<collision>
		  <origin xyz="0 0 0" rpy="0 0 0" />
		  <geometry>
		    <mesh filename="file://$(find chessaton_description)/meshes/chessaton_link4.STL" />
		  </geometry>
		</collision>

        <inertial>
            <origin xyz="0.00247057855143362 -0.0269175108707789 -0.0100531530882181" rpy="0 0 0" />
            <mass value="0.0465" />
            <inertia
              ixx="1.44068897410675E-05"
              ixy="-4.53376917177043E-07"
              ixz="-1.53060923766455E-09"
              iyy="1.04605048186758E-05"
              iyz="-4.07815450494968E-09"
              izz="7.71225538228526E-06" />
        </inertial>
	</link>

	<joint name="gripper_joint" type="fixed">
	  <origin xyz="0.070608 -0.033636 -0.0087075" rpy="0 0 0" />
	  <parent link="chessaton_link4" />
	  <child link="chessaton_gripper" />
	  <axis xyz="0 0 0" />
	</joint>

    <xacro:chessaton_hand
        virtual_dof="$(arg virtual_dof)"
    />

    <xacro:if value="$(arg use_camera)">
        <xacro:sensor_camera /> 
    </xacro:if>

      <!-- Transmission macro -->
  <!-- <xacro:macro name="SimpleTransmissionPosition" params="joint n">
    <transmission name="tran${n}">
      <type>transmission_interface/SimpleTransmission</type>
      <joint name="${joint}">
        <hardwareInterface>hardware_interface/PositionJointInterface</hardwareInterface>
      </joint>
      <actuator name="motor${n}">
        <mechanicalReduction>1</mechanicalReduction>
      </actuator>
    </transmission>
  </xacro:macro> -->

  <!-- Transmission macro -->
  <!-- <xacro:macro name="SimpleTransmissionEffort" params="joint n">
    <transmission name="tran${n}">
      <type>transmission_interface/SimpleTransmission</type>
      <joint name="${joint}">
        <hardwareInterface>hardware_interface/EffortJointInterface</hardwareInterface>
      </joint>
      <actuator name="motor${n}">
        <mechanicalReduction>1</mechanicalReduction>
      </actuator>
    </transmission>
  </xacro:macro> -->

  <!-- <xacro:SimpleTransmissionEffort n="1" joint="chessaton_joint1" />

  <xacro:SimpleTransmissionEffort n="2" joint="chessaton_joint2" />

  <xacro:SimpleTransmissionEffort n="3" joint="chessaton_joint3" />

  <xacro:SimpleTransmissionEffort n="4" joint="chessaton_joint4" />

  <xacro:SimpleTransmissionEffort n="5" joint="left_finger_joint" />

  <xacro:SimpleTransmissionEffort n="6" joint="right_finger_joint" /> -->

    <xacro:gz_ros2_control
        ros2_controller_parameters="$(arg ros2_controller_parameters)"
    />

    <xacro:mein_ros2_control
        ros2_control="$(arg ros2_control)"
        prefix="$(arg prefix)" 
        ros2_control_plugin="$(arg ros2_control_plugin)"
        ros2_control_command_interface="$(arg ros2_control_command_interface)"
        ros2_controller_parameters="$(arg ros2_controller_parameters)"
    />

</robot>